<?xml version="1.0" ?>
<sdf version='1.7'>
  <model name='rover'>
    <static>false</static> 
    <joint name='world-fae' type='fixed'>
      <pose relative_to='__model__'>0 0 0 0 -0 1.57</pose>
      <parent>world</parent>
      <child>imu_link</child>
    </joint>
    <link name='imu_link'>
      <pose relative_to='world-fae'>0 0 0 0 -0 0</pose>
      <inertial>
        <pose>-0.342593 -3.7e-05 -0.007014 0 -0 0</pose>
        <mass>4.3741</mass>
        <inertia>
          <ixx>0.175826</ixx>
          <ixy>9.2341e-05</ixy>
          <ixz>-0.00256896</ixz>
          <iyy>0.146867</iyy>
          <iyz>1.14961e-06</iyz>
          <izz>0.318144</izz>
        </inertia>
      </inertial>
      <collision name='imu_link_collision'>
        <pose>0 -0.2572 0 0 -0 0</pose>
        <geometry>
          <mesh>
            <scale>0.001 0.001 0.001</scale>
            <uri>package://meshes/2020+400mm.stl</uri>
          </mesh>
        </geometry>
        <surface>
          <contact>
            <ode/>
          </contact>
          <friction>
            <ode/>
          </friction>
        </surface>
      </collision>
      <collision name='imu_link_fixed_joint_lump__front-left-bracket_collision_1'>
        <pose>0.0135 0.22 -0.0135 0 0 -3.13819</pose>
        <geometry>
          <mesh>
            <scale>0.001 0.001 0.001</scale>
            <uri>package://meshes/2020+Super+Corner+Bracket.stl</uri>
          </mesh>
        </geometry>
        <surface>
          <contact>
            <ode/>
          </contact>
          <friction>
            <ode/>
          </friction>
        </surface>
      </collision>
      <collision name='imu_link_fixed_joint_lump__left-aluminum-extrusion_collision_2'>
        <pose>-0.35 0.2065 0 0 -0 1.57</pose>
        <geometry>
          <mesh>
            <scale>0.001 0.001 0.001</scale>
            <uri>package://meshes/2020+800mm.stl</uri>
          </mesh>
        </geometry>
        <surface>
          <contact>
            <ode/>
          </contact>
          <friction>
            <ode/>
          </friction>
        </surface>
      </collision>
      <collision name='imu_link_fixed_joint_lump__lower-middle-aluminum-extrusion_collision_3'>
        <pose>-0.6 -0.2572 0 0 -0 0</pose>
        <geometry>
          <mesh>
            <scale>0.001 0.001 0.001</scale>
            <uri>package://meshes/2020+400mm.stl</uri>
          </mesh>
        </geometry>
        <surface>
          <contact>
            <ode/>
          </contact>
          <friction>
            <ode/>
          </friction>
        </surface>
      </collision>
      <collision name='imu_link_fixed_joint_lump__left-middle-TBracket_collision_4'>
        <pose>-0.61 0.217 0.013 -3.13819 0 0</pose>
        <geometry>
          <mesh>
            <scale>0.001 0.001 0.001</scale>
            <uri>package://meshes/2020+T_Bracket_60x60x20.stl</uri>
          </mesh>
        </geometry>
        <surface>
          <contact>
            <ode/>
          </contact>
          <friction>
            <ode/>
          </friction>
        </surface>
      </collision>
      <collision name='imu_link_fixed_joint_lump__left-pillow-bearing_collision_5'>
        <pose>-0.427 0.2065 -0.01 3.14159 -0.003407 3.14159</pose>
        <geometry>
          <mesh>
            <scale>0.001 0.001 0.001</scale>
            <uri>package://meshes/Pillow+Bearking+XIKE+K004.stl</uri>
          </mesh>
        </geometry>
        <surface>
          <contact>
            <ode/>
          </contact>
          <friction>
            <ode/>
          </friction>
        </surface>
      </collision>
      <collision name='imu_link_fixed_joint_lump__middle-aluminum-extrusion_collision_6'>
        <pose>-0.38 -0.2572 0 0 -0 0</pose>
        <geometry>
          <mesh>
            <scale>0.001 0.001 0.001</scale>
            <uri>package://meshes/2020+400mm.stl</uri>
          </mesh>
        </geometry>
        <surface>
          <contact>
            <ode/>
          </contact>
          <friction>
            <ode/>
          </friction>
        </surface>
      </collision>
      <collision name='imu_link_fixed_joint_lump__front-right-bracket_collision_7'>
        <pose>0.0135 -0.22 0.0135 3.14159 -0.003407 -3.14159</pose>
        <geometry>
          <mesh>
            <scale>0.001 0.001 0.001</scale>
            <uri>package://meshes/2020+Super+Corner+Bracket.stl</uri>
          </mesh>
        </geometry>
        <surface>
          <contact>
            <ode/>
          </contact>
          <friction>
            <ode/>
          </friction>
        </surface>
      </collision>
      <collision name='imu_link_fixed_joint_lump__right-aluminum-extrusion_collision_8'>
        <pose>-0.35 -0.2065 0 0 -0 1.57</pose>
        <geometry>
          <mesh>
            <scale>0.001 0.001 0.001</scale>
            <uri>package://meshes/2020+800mm.stl</uri>
          </mesh>
        </geometry>
        <surface>
          <contact>
            <ode/>
          </contact>
          <friction>
            <ode/>
          </friction>
        </surface>
      </collision>
      <collision name='imu_link_fixed_joint_lump__right-middle-TBracket_collision_9'>
        <pose>-0.59 -0.217 0.013 -3.13819 -0 -3.13819</pose>
        <geometry>
          <mesh>
            <scale>0.001 0.001 0.001</scale>
            <uri>package://meshes/2020+T_Bracket_60x60x20.stl</uri>
          </mesh>
        </geometry>
        <surface>
          <contact>
            <ode/>
          </contact>
          <friction>
            <ode/>
          </friction>
        </surface>
      </collision>
      <collision name='imu_link_fixed_joint_lump__right-pillow-bearing_collision_10'>
        <pose>-0.427 -0.2065 -0.01 3.14159 -0.003407 3.14159</pose>
        <geometry>
          <mesh>
            <scale>0.001 0.001 0.001</scale>
            <uri>package://meshes/Pillow+Bearking+XIKE+K004.stl</uri>
          </mesh>
        </geometry>
        <surface>
          <contact>
            <ode/>
          </contact>
          <friction>
            <ode/>
          </friction>
        </surface>
      </collision>
      <visual name='imu_link_visual'>
        <pose>0 -0.2572 0 0 -0 0</pose>
        <geometry>
          <mesh>
            <scale>0.001 0.001 0.001</scale>
            <uri>package://meshes/2020+400mm.stl</uri>
          </mesh>
        </geometry>
        <material>
          <script>
            <name>Gazebo/Grey</name>
            <uri>file://media/materials/scripts/gazebo.material</uri>
          </script>
        </material>
      </visual>
      <visual name='imu_link_fixed_joint_lump__front-left-bracket_visual_1'>
        <pose>0.0135 0.22 -0.0135 0 0 -3.13819</pose>
        <geometry>
          <mesh>
            <scale>0.001 0.001 0.001</scale>
            <uri>package://meshes/2020+Super+Corner+Bracket.stl</uri>
          </mesh>
        </geometry>
        <material>
          <script>
            <name>Gazebo/Blue</name>
            <uri>file://media/materials/scripts/gazebo.material</uri>
          </script>
        </material>
      </visual>
      <visual name='imu_link_fixed_joint_lump__left-aluminum-extrusion_visual_2'>
        <pose>-0.35 0.2065 0 0 -0 1.57</pose>
        <geometry>
          <mesh>
            <scale>0.001 0.001 0.001</scale>
            <uri>package://meshes/2020+800mm.stl</uri>
          </mesh>
        </geometry>
        <material>
          <script>
            <name>Gazebo/Grey</name>
            <uri>file://media/materials/scripts/gazebo.material</uri>
          </script>
        </material>
      </visual>
      <visual name='imu_link_fixed_joint_lump__lower-middle-aluminum-extrusion_visual_3'>
        <pose>-0.6 -0.2572 0 0 -0 0</pose>
        <geometry>
          <mesh>
            <scale>0.001 0.001 0.001</scale>
            <uri>package://meshes/2020+400mm.stl</uri>
          </mesh>
        </geometry>
        <material>
          <script>
            <name>Gazebo/Grey</name>
            <uri>file://media/materials/scripts/gazebo.material</uri>
          </script>
        </material>
      </visual>
      <visual name='imu_link_fixed_joint_lump__left-middle-TBracket_visual_4'>
        <pose>-0.61 0.217 0.013 -3.13819 0 0</pose>
        <geometry>
          <mesh>
            <scale>0.001 0.001 0.001</scale>
            <uri>package://meshes/2020+T_Bracket_60x60x20.stl</uri>
          </mesh>
        </geometry>
        <material>
          <script>
            <name>Gazebo/Blue</name>
            <uri>file://media/materials/scripts/gazebo.material</uri>
          </script>
        </material>
      </visual>
      <visual name='imu_link_fixed_joint_lump__left-pillow-bearing_visual_5'>
        <pose>-0.427 0.2065 -0.01 3.14159 -0.003407 3.14159</pose>
        <geometry>
          <mesh>
            <scale>0.001 0.001 0.001</scale>
            <uri>package://meshes/Pillow+Bearking+XIKE+K004.stl</uri>
          </mesh>
        </geometry>
        <material>
          <script>
            <name>Gazebo/Grey</name>
            <uri>file://media/materials/scripts/gazebo.material</uri>
          </script>
        </material>
      </visual>
      <visual name='imu_link_fixed_joint_lump__middle-aluminum-extrusion_visual_6'>
        <pose>-0.38 -0.2572 0 0 -0 0</pose>
        <geometry>
          <mesh>
            <scale>0.001 0.001 0.001</scale>
            <uri>package://meshes/2020+400mm.stl</uri>
          </mesh>
        </geometry>
        <material>
          <script>
            <name>Gazebo/Grey</name>
            <uri>file://media/materials/scripts/gazebo.material</uri>
          </script>
        </material>
      </visual>
      <visual name='imu_link_fixed_joint_lump__front-right-bracket_visual_7'>
        <pose>0.0135 -0.22 0.0135 3.14159 -0.003407 -3.14159</pose>
        <geometry>
          <mesh>
            <scale>0.001 0.001 0.001</scale>
            <uri>package://meshes/2020+Super+Corner+Bracket.stl</uri>
          </mesh>
        </geometry>
        <material>
          <script>
            <name>Gazebo/Blue</name>
            <uri>file://media/materials/scripts/gazebo.material</uri>
          </script>
        </material>
      </visual>
      <visual name='imu_link_fixed_joint_lump__right-aluminum-extrusion_visual_8'>
        <pose>-0.35 -0.2065 0 0 -0 1.57</pose>
        <geometry>
          <mesh>
            <scale>0.001 0.001 0.001</scale>
            <uri>package://meshes/2020+800mm.stl</uri>
          </mesh>
        </geometry>
        <material>
          <script>
            <name>Gazebo/Grey</name>
            <uri>file://media/materials/scripts/gazebo.material</uri>
          </script>
        </material>
      </visual>
      <visual name='imu_link_fixed_joint_lump__right-middle-TBracket_visual_9'>
        <pose>-0.59 -0.217 0.013 -3.13819 -0 -3.13819</pose>
        <geometry>
          <mesh>
            <scale>0.001 0.001 0.001</scale>
            <uri>package://meshes/2020+T_Bracket_60x60x20.stl</uri>
          </mesh>
        </geometry>
        <material>
          <script>
            <name>Gazebo/Blue</name>
            <uri>file://media/materials/scripts/gazebo.material</uri>
          </script>
        </material>
      </visual>
      <visual name='imu_link_fixed_joint_lump__right-pillow-bearing_visual_10'>
        <pose>-0.427 -0.2065 -0.01 3.14159 -0.003407 3.14159</pose>
        <geometry>
          <mesh>
            <scale>0.001 0.001 0.001</scale>
            <uri>package://meshes/Pillow+Bearking+XIKE+K004.stl</uri>
          </mesh>
        </geometry>
        <material>
          <script>
            <name>Gazebo/Grey</name>
            <uri>file://media/materials/scripts/gazebo.material</uri>
          </script>
        </material>
      </visual>
      <sensor name='imu_sensor' type='imu'>
        <always_on>1</always_on>
        <update_rate>100</update_rate>
        <visualize>1</visualize>
        <topic>imu</topic>
        <plugin name='imu_plugin' filename='libgazebo_ros_imu_sensor.so'>
          <topicName>imu</topicName>
          <bodyName>imu_link</bodyName>
          <updateRateHZ>100.0</updateRateHZ>
          <gaussianNoise>0.0</gaussianNoise>
          <xyzOffset>0 0 0</xyzOffset>
          <rpyOffset>0 0 0</rpyOffset>
          <frameName>imu_link</frameName>
        </plugin>
      </sensor>
    </link>
    <joint name='lpb-ls' type='revolute'>
      <pose relative_to='imu_link'>-0.427 0.1665 -0.0365 0 -0 0</pose>
      <parent>imu_link</parent>
      <child>left-shaft</child>
      <axis>
        <xyz>0 1 0</xyz>
        <limit>
          <lower>-1e+16</lower>
          <upper>1e+16</upper>
        </limit>
        <dynamics>
          <spring_reference>0</spring_reference>
          <spring_stiffness>0</spring_stiffness>
        </dynamics>
      </axis>
    </joint>
    <link name='left-shaft'>
      <pose relative_to='lpb-ls'>0 0 0 0 -0 0</pose>
      <inertial>
        <pose>0 0 0 0 -0 0</pose>
        <mass>0.74065</mass>
        <inertia>
          <ixx>0.00555561</ixx>
          <ixy>0</ixy>
          <ixz>0</ixz>
          <iyy>1.4813e-06</iyy>
          <iyz>0</iyz>
          <izz>0.00555561</izz>
        </inertia>
      </inertial>
      <collision name='left-shaft_collision'>
        <pose>0 -0.15 0 0 -0 0</pose>
        <geometry>
          <mesh>
            <scale>0.001 0.001 0.001</scale>
            <uri>package://meshes/20mm+shaft.stl</uri>
          </mesh>
        </geometry>
        <surface>
          <contact>
            <ode/>
          </contact>
          <friction>
            <ode/>
          </friction>
        </surface>
      </collision>
      <visual name='left-shaft_visual'>
        <pose>0 -0.15 0 0 -0 0</pose>
        <geometry>
          <mesh>
            <scale>0.001 0.001 0.001</scale>
            <uri>package://meshes/20mm+shaft.stl</uri>
          </mesh>
        </geometry>
        <material>
          <script>
            <name>Gazebo/Grey</name>
            <uri>file://media/materials/scripts/gazebo.material</uri>
          </script>
        </material>
      </visual>
    </link>
    <joint name='ls-lsb' type='revolute'>
      <pose relative_to='left-shaft'>0 0.1025 0 0 -0 0</pose>
      <parent>left-shaft</parent>
      <child>Suspension-Bar-Left</child>
      <axis>
        <xyz>0 1 0</xyz>
        <limit>
          <lower>-1e+16</lower>
          <upper>1e+16</upper>
        </limit>
        <dynamics>
          <spring_reference>0</spring_reference>
          <spring_stiffness>0</spring_stiffness>
        </dynamics>
      </axis>
    </joint>
    <link name='Suspension-Bar-Left'>
      <pose relative_to='ls-lsb'>0 0 0 0 -0 0</pose>
      <inertial>
        <pose>0.000227 0 -0.265149 0 -0 0</pose>
        <mass>0.80005</mass>
        <inertia>
          <ixx>0.109194</ixx>
          <ixy>0</ixy>
          <ixz>9.48451e-05</ixz>
          <iyy>0.295663</iyy>
          <iyz>0</iyz>
          <izz>0.370607</izz>
        </inertia>
      </inertial>
      <collision name='Suspension-Bar-Left_collision'>
        <pose>0 0 0 1.57 -0 0</pose>
        <geometry>
          <mesh>
            <scale>1 1 1</scale>
            <uri>package://meshes/Suspension-Bar.stl</uri>
          </mesh>
        </geometry>
        <surface>
          <contact>
            <ode/>
          </contact>
          <friction>
            <ode/>
          </friction>
        </surface>
      </collision>
      <collision name='Suspension-Bar-Left_fixed_joint_lump__2020-wheel-back-extrusion-left_collision_1'>
        <pose>0 0 0 1.57 -0 0</pose>
        <geometry>
          <mesh>
            <scale>1 1 1</scale>
            <uri>package://meshes/2020-extrusion-left.stl</uri>
          </mesh>
        </geometry>
        <surface>
          <contact>
            <ode/>
          </contact>
          <friction>
            <ode/>
          </friction>
        </surface>
      </collision>
      <collision name='Suspension-Bar-Left_fixed_joint_lump__back-left-pillow-bearing_collision_2'>
        <pose>0 0 0 1.57 -0 0</pose>
        <geometry>
          <mesh>
            <scale>1 1 1</scale>
            <uri>package://meshes/wheel-bearing-left.stl</uri>
          </mesh>
        </geometry>
        <surface>
          <contact>
            <ode/>
          </contact>
          <friction>
            <ode/>
          </friction>
        </surface>
      </collision>
      <collision name='Suspension-Bar-Left_fixed_joint_lump__2020-wheel-front-extrusion-left_collision_3'>
        <pose>0 0 0 1.57 -0 0</pose>
        <geometry>
          <mesh>
            <scale>1 1 1</scale>
            <uri>package://meshes/2020-extrusion-right.stl</uri>
          </mesh>
        </geometry>
        <surface>
          <contact>
            <ode/>
          </contact>
          <friction>
            <ode/>
          </friction>
        </surface>
      </collision>
      <collision name='Suspension-Bar-Left_fixed_joint_lump__front-left-pillow-bearing_collision_4'>
        <pose>0 0 0 1.57 -0 0</pose>
        <geometry>
          <mesh>
            <scale>1 1 1</scale>
            <uri>package://meshes/wheel-bearing-right.stl</uri>
          </mesh>
        </geometry>
        <surface>
          <contact>
            <ode/>
          </contact>
          <friction>
            <ode/>
          </friction>
        </surface>
      </collision>
      <visual name='Suspension-Bar-Left_visual'>
        <pose>0 0 0 1.57 -0 0</pose>
        <geometry>
          <mesh>
            <scale>1 1 1</scale>
            <uri>package://meshes/Suspension-Bar.stl</uri>
          </mesh>
        </geometry>
        <material>
          <script>
            <name>Gazebo/Grey</name>
            <uri>file://media/materials/scripts/gazebo.material</uri>
          </script>
        </material>
      </visual>
      <visual name='Suspension-Bar-Left_fixed_joint_lump__2020-wheel-back-extrusion-left_visual_1'>
        <pose>0 0 0 1.57 -0 0</pose>
        <geometry>
          <mesh>
            <scale>1 1 1</scale>
            <uri>package://meshes/2020-extrusion-left.stl</uri>
          </mesh>
        </geometry>
        <material>
          <script>
            <name>Gazebo/Grey</name>
            <uri>file://media/materials/scripts/gazebo.material</uri>
          </script>
        </material>
      </visual>
      <visual name='Suspension-Bar-Left_fixed_joint_lump__back-left-pillow-bearing_visual_2'>
        <pose>0 0 0 1.57 -0 0</pose>
        <geometry>
          <mesh>
            <scale>1 1 1</scale>
            <uri>package://meshes/wheel-bearing-left.stl</uri>
          </mesh>
        </geometry>
        <material>
          <script>
            <name>Gazebo/Grey</name>
            <uri>file://media/materials/scripts/gazebo.material</uri>
          </script>
        </material>
      </visual>
      <visual name='Suspension-Bar-Left_fixed_joint_lump__2020-wheel-front-extrusion-left_visual_3'>
        <pose>0 0 0 1.57 -0 0</pose>
        <geometry>
          <mesh>
            <scale>1 1 1</scale>
            <uri>package://meshes/2020-extrusion-right.stl</uri>
          </mesh>
        </geometry>
        <material>
          <script>
            <name>Gazebo/Grey</name>
            <uri>file://media/materials/scripts/gazebo.material</uri>
          </script>
        </material>
      </visual>
      <visual name='Suspension-Bar-Left_fixed_joint_lump__front-left-pillow-bearing_visual_4'>
        <pose>0 0 0 1.57 -0 0</pose>
        <geometry>
          <mesh>
            <scale>1 1 1</scale>
            <uri>package://meshes/wheel-bearing-right.stl</uri>
          </mesh>
        </geometry>
        <material>
          <script>
            <name>Gazebo/Grey</name>
            <uri>file://media/materials/scripts/gazebo.material</uri>
          </script>
        </material>
      </visual>
    </link>
    <joint name='blpb_flw' type='revolute'>
      <pose relative_to='Suspension-Bar-Left'>-0.789 0 -0.788 0 -0 0</pose>
      <parent>Suspension-Bar-Left</parent>
      <child>back-left-wheel</child>
      <axis>
        <xyz>0 1 0</xyz>
        <limit>
          <lower>-1e+16</lower>
          <upper>1e+16</upper>
        </limit>
        <dynamics>
          <spring_reference>0</spring_reference>
          <spring_stiffness>0</spring_stiffness>
        </dynamics>
      </axis>
    </joint>
    <link name='back-left-wheel'>
      <pose relative_to='blpb_flw'>0 0 0 0 -0 0</pose>
      <inertial>
        <pose>0 0 0 0 -0 0</pose>
        <mass>2.003</mass>
        <inertia>
          <ixx>0.015139</ixx>
          <ixy>0</ixy>
          <ixz>0</ixz>
          <iyy>0.0169253</iyy>
          <iyz>0</iyz>
          <izz>0.0151393</izz>
        </inertia>
      </inertial>
      <collision name='back-left-wheel_collision'>
        <pose>-0.791 0 -0.788 -1.57 0 0</pose>
        <geometry>
          <mesh>
            <scale>1 1 1</scale>
            <uri>package://meshes/Honeycomb-wheel-right.stl</uri>
          </mesh>
        </geometry>
        <surface>
          <contact>
            <ode/>
          </contact>
          <friction>
            <ode/>
          </friction>
        </surface>
      </collision>
      <visual name='back-left-wheel_visual'>
        <pose>-0.791 0 -0.788 -1.57 0 0</pose>
        <geometry>
          <mesh>
            <scale>1 1 1</scale>
            <uri>package://meshes/Honeycomb-wheel-right.stl</uri>
          </mesh>
        </geometry>
        <material>
          <script>
            <name>Gazebo/Yellow</name>
            <uri>file://media/materials/scripts/gazebo.material</uri>
          </script>
        </material>
      </visual>
    </link>
    <joint name='flpb_flw' type='revolute'>
      <pose relative_to='Suspension-Bar-Left'>0.791 0 -0.788 0 -0 0</pose>
      <parent>Suspension-Bar-Left</parent>
      <child>front-left-wheel</child>
      <axis>
        <xyz>0 1 0</xyz>
        <limit>
          <lower>-1e+16</lower>
          <upper>1e+16</upper>
        </limit>
        <dynamics>
          <spring_reference>0</spring_reference>
          <spring_stiffness>0</spring_stiffness>
        </dynamics>
      </axis>
    </joint>
    <link name='front-left-wheel'>
      <pose relative_to='flpb_flw'>0 0 0 0 -0 0</pose>
      <inertial>
        <pose>0 0 0 0 -0 0</pose>
        <mass>2.003</mass>
        <inertia>
          <ixx>0.015139</ixx>
          <ixy>0</ixy>
          <ixz>0</ixz>
          <iyy>0.0169253</iyy>
          <iyz>0</iyz>
          <izz>0.0151393</izz>
        </inertia>
      </inertial>
      <collision name='front-left-wheel_collision'>
        <pose>-0.791 0 -0.788 -1.57 0 0</pose>
        <geometry>
          <mesh>
            <scale>1 1 1</scale>
            <uri>package://meshes/Honeycomb-wheel-right.stl</uri>
          </mesh>
        </geometry>
        <surface>
          <contact>
            <ode/>
          </contact>
          <friction>
            <ode/>
          </friction>
        </surface>
      </collision>
      <visual name='front-left-wheel_visual'>
        <pose>-0.791 0 -0.788 -1.57 0 0</pose>
        <geometry>
          <mesh>
            <scale>1 1 1</scale>
            <uri>package://meshes/Honeycomb-wheel-right.stl</uri>
          </mesh>
        </geometry>
        <material>
          <script>
            <name>Gazebo/Yellow</name>
            <uri>file://media/materials/scripts/gazebo.material</uri>
          </script>
        </material>
      </visual>
    </link>
    <joint name='rpb-rs' type='revolute'>
      <pose relative_to='imu_link'>-0.427 -0.1665 -0.0365 0 -0 0</pose>
      <parent>imu_link</parent>
      <child>right-shaft</child>
      <axis>
        <xyz>0 1 0</xyz>
        <limit>
          <lower>-1e+16</lower>
          <upper>1e+16</upper>
        </limit>
        <dynamics>
          <spring_reference>0</spring_reference>
          <spring_stiffness>0</spring_stiffness>
        </dynamics>
      </axis>
    </joint>
    <link name='right-shaft'>
      <pose relative_to='rpb-rs'>0 0 0 0 -0 0</pose>
      <inertial>
        <pose>0 0 0 0 -0 0</pose>
        <mass>0.74065</mass>
        <inertia>
          <ixx>0.00555561</ixx>
          <ixy>0</ixy>
          <ixz>0</ixz>
          <iyy>1.4813e-06</iyy>
          <iyz>0</iyz>
          <izz>0.00555561</izz>
        </inertia>
      </inertial>
      <collision name='right-shaft_collision'>
        <pose>0 -0.15 0 0 -0 0</pose>
        <geometry>
          <mesh>
            <scale>0.001 0.001 0.001</scale>
            <uri>package://meshes/20mm+shaft.stl</uri>
          </mesh>
        </geometry>
        <surface>
          <contact>
            <ode/>
          </contact>
          <friction>
            <ode/>
          </friction>
        </surface>
      </collision>
      <visual name='right-shaft_visual'>
        <pose>0 -0.15 0 0 -0 0</pose>
        <geometry>
          <mesh>
            <scale>0.001 0.001 0.001</scale>
            <uri>package://meshes/20mm+shaft.stl</uri>
          </mesh>
        </geometry>
        <material>
          <script>
            <name>Gazebo/Grey</name>
            <uri>file://media/materials/scripts/gazebo.material</uri>
          </script>
        </material>
      </visual>
    </link>
    <joint name='rs-rsb' type='revolute'>
      <pose relative_to='right-shaft'>0 -0.0875 0 0 -0 0</pose>
      <parent>right-shaft</parent>
      <child>Suspension-Bar-Right</child>
      <axis>
        <xyz>0 1 0</xyz>
        <limit>
          <lower>-1e+16</lower>
          <upper>1e+16</upper>
        </limit>
        <dynamics>
          <spring_reference>0</spring_reference>
          <spring_stiffness>0</spring_stiffness>
        </dynamics>
      </axis>
    </joint>
    <link name='Suspension-Bar-Right'>
      <pose relative_to='rs-rsb'>0 0 0 0 -0 0</pose>
      <inertial>
        <pose>0 0 -0.244291 0 -0 0</pose>
        <mass>0.85945</mass>
        <inertia>
          <ixx>0.110746</ixx>
          <ixy>0</ixy>
          <ixz>0</ixz>
          <iyy>0.477281</iyy>
          <iyz>0</iyz>
          <izz>0.36663</izz>
        </inertia>
      </inertial>
      <collision name='Suspension-Bar-Right_collision'>
        <pose>0 0 0 1.57 -0 0</pose>
        <geometry>
          <mesh>
            <scale>1 1 1</scale>
            <uri>package://meshes/Suspension-Bar.stl</uri>
          </mesh>
        </geometry>
        <surface>
          <contact>
            <ode/>
          </contact>
          <friction>
            <ode/>
          </friction>
        </surface>
      </collision>
      <collision name='Suspension-Bar-Right_fixed_joint_lump__2020-wheel-back-extrusion-right_collision_1'>
        <pose>0 0 0 1.57 -0 0</pose>
        <geometry>
          <mesh>
            <scale>1 1 1</scale>
            <uri>package://meshes/2020-extrusion-left.stl</uri>
          </mesh>
        </geometry>
        <surface>
          <contact>
            <ode/>
          </contact>
          <friction>
            <ode/>
          </friction>
        </surface>
      </collision>
      <collision name='Suspension-Bar-Right_fixed_joint_lump__back-right-pillow-bearing_collision_2'>
        <pose>0 0 0 1.57 -0 0</pose>
        <geometry>
          <mesh>
            <scale>1 1 1</scale>
            <uri>package://meshes/wheel-bearing-left.stl</uri>
          </mesh>
        </geometry>
        <surface>
          <contact>
            <ode/>
          </contact>
          <friction>
            <ode/>
          </friction>
        </surface>
      </collision>
      <collision name='Suspension-Bar-Right_fixed_joint_lump__2020-wheel-front-extrusion-right_collision_3'>
        <pose>0 0 0 1.57 -0 0</pose>
        <geometry>
          <mesh>
            <scale>1 1 1</scale>
            <uri>package://meshes/2020-extrusion-right.stl</uri>
          </mesh>
        </geometry>
        <surface>
          <contact>
            <ode/>
          </contact>
          <friction>
            <ode/>
          </friction>
        </surface>
      </collision>
      <collision name='Suspension-Bar-Right_fixed_joint_lump__front-right-pillow-bearing_collision_4'>
        <pose>0 0 0 1.57 -0 0</pose>
        <geometry>
          <mesh>
            <scale>1 1 1</scale>
            <uri>package://meshes/wheel-bearing-right.stl</uri>
          </mesh>
        </geometry>
        <surface>
          <contact>
            <ode/>
          </contact>
          <friction>
            <ode/>
          </friction>
        </surface>
      </collision>
      <visual name='Suspension-Bar-Right_visual'>
        <pose>0 0 0 1.57 -0 0</pose>
        <geometry>
          <mesh>
            <scale>1 1 1</scale>
            <uri>package://meshes/Suspension-Bar.stl</uri>
          </mesh>
        </geometry>
        <material>
          <script>
            <name>Gazebo/Grey</name>
            <uri>file://media/materials/scripts/gazebo.material</uri>
          </script>
        </material>
      </visual>
      <visual name='Suspension-Bar-Right_fixed_joint_lump__2020-wheel-back-extrusion-right_visual_1'>
        <pose>0 0 0 1.57 -0 0</pose>
        <geometry>
          <mesh>
            <scale>1 1 1</scale>
            <uri>package://meshes/2020-extrusion-left.stl</uri>
          </mesh>
        </geometry>
        <material>
          <script>
            <name>Gazebo/Grey</name>
            <uri>file://media/materials/scripts/gazebo.material</uri>
          </script>
        </material>
      </visual>
      <visual name='Suspension-Bar-Right_fixed_joint_lump__back-right-pillow-bearing_visual_2'>
        <pose>0 0 0 1.57 -0 0</pose>
        <geometry>
          <mesh>
            <scale>1 1 1</scale>
            <uri>package://meshes/wheel-bearing-left.stl</uri>
          </mesh>
        </geometry>
        <material>
          <script>
            <name>Gazebo/Grey</name>
            <uri>file://media/materials/scripts/gazebo.material</uri>
          </script>
        </material>
      </visual>
      <visual name='Suspension-Bar-Right_fixed_joint_lump__2020-wheel-front-extrusion-right_visual_3'>
        <pose>0 0 0 1.57 -0 0</pose>
        <geometry>
          <mesh>
            <scale>1 1 1</scale>
            <uri>package://meshes/2020-extrusion-right.stl</uri>
          </mesh>
        </geometry>
        <material>
          <script>
            <name>Gazebo/Grey</name>
            <uri>file://media/materials/scripts/gazebo.material</uri>
          </script>
        </material>
      </visual>
      <visual name='Suspension-Bar-Right_fixed_joint_lump__front-right-pillow-bearing_visual_4'>
        <pose>0 0 0 1.57 -0 0</pose>
        <geometry>
          <mesh>
            <scale>1 1 1</scale>
            <uri>package://meshes/wheel-bearing-right.stl</uri>
          </mesh>
        </geometry>
        <material>
          <script>
            <name>Gazebo/Grey</name>
            <uri>file://media/materials/scripts/gazebo.material</uri>
          </script>
        </material>
      </visual>
    </link>
    <joint name='brpb_brw' type='revolute'>
      <pose relative_to='Suspension-Bar-Right'>-0.776 0 -0.776 0 -0 0</pose>
      <parent>Suspension-Bar-Right</parent>
      <child>back-right-wheel</child>
      <axis>
        <xyz>0 1 0</xyz>
        <limit>
          <lower>-1e+16</lower>
          <upper>1e+16</upper>
        </limit>
        <dynamics>
          <spring_reference>0</spring_reference>
          <spring_stiffness>0</spring_stiffness>
        </dynamics>
      </axis>
    </joint>
    <link name='back-right-wheel'>
      <pose relative_to='brpb_brw'>0 0 0 0 -0 0</pose>
      <inertial>
        <pose>0 0 0 0 -0 0</pose>
        <mass>2.003</mass>
        <inertia>
          <ixx>0.015139</ixx>
          <ixy>0</ixy>
          <ixz>0</ixz>
          <iyy>0.0169253</iyy>
          <iyz>0</iyz>
          <izz>0.0151393</izz>
        </inertia>
      </inertial>
      <collision name='back-right-wheel_collision'>
        <pose>0.791 -0.25 0.788 1.57 0 -3.13819</pose>
        <geometry>
          <mesh>
            <scale>1 1 1</scale>
            <uri>package://meshes/Honeycomb-wheel-right.stl</uri>
          </mesh>
        </geometry>
        <surface>
          <contact>
            <ode/>
          </contact>
          <friction>
            <ode/>
          </friction>
        </surface>
      </collision>
      <visual name='back-right-wheel_visual'>
        <pose>0.791 -0.25 0.788 1.57 0 -3.13819</pose>
        <geometry>
          <mesh>
            <scale>1 1 1</scale>
            <uri>package://meshes/Honeycomb-wheel-right.stl</uri>
          </mesh>
        </geometry>
        <material>
          <script>
            <name>Gazebo/Yellow</name>
            <uri>file://media/materials/scripts/gazebo.material</uri>
          </script>
        </material>
      </visual>
    </link>
    <joint name='frpb_frw' type='revolute'>
      <pose relative_to='Suspension-Bar-Right'>0.776 0 -0.776 0 -0 0</pose>
      <parent>Suspension-Bar-Right</parent>
      <child>front-right-wheel</child>
      <axis>
        <xyz>0 1 0</xyz>
        <limit>
          <lower>-1e+16</lower>
          <upper>1e+16</upper>
        </limit>
        <dynamics>
          <spring_reference>0</spring_reference>
          <spring_stiffness>0</spring_stiffness>
        </dynamics>
      </axis>
    </joint>
    <link name='front-right-wheel'>
      <pose relative_to='frpb_frw'>0 0 0 0 -0 0</pose>
      <inertial>
        <pose>0 0 0 0 -0 0</pose>
        <mass>2.003</mass>
        <inertia>
          <ixx>0.015139</ixx>
          <ixy>0</ixy>
          <ixz>0</ixz>
          <iyy>0.0169253</iyy>
          <iyz>0</iyz>
          <izz>0.0151393</izz>
        </inertia>
      </inertial>
      <collision name='front-right-wheel_collision'>
        <pose>0.791 -0.25 0.788 1.57 0 -3.13819</pose>
        <geometry>
          <mesh>
            <scale>1 1 1</scale>
            <uri>package://meshes/Honeycomb-wheel-right.stl</uri>
          </mesh>
        </geometry>
        <surface>
          <contact>
            <ode/>
          </contact>
          <friction>
            <ode/>
          </friction>
        </surface>
      </collision>
      <visual name='front-right-wheel_visual'>
        <pose>0.791 -0.25 0.788 1.57 0 -3.13819</pose>
        <geometry>
          <mesh>
            <scale>1 1 1</scale>
            <uri>package://meshes/Honeycomb-wheel-right.stl</uri>
          </mesh>
        </geometry>
        <material>
          <script>
            <name>Gazebo/Yellow</name>
            <uri>file://media/materials/scripts/gazebo.material</uri>
          </script>
        </material>
      </visual>
    </link>
    <plugin name='arducopter_plugin' filename='libArduPilotPlugin.so'>
      <fdm_addr>127.0.0.1</fdm_addr>
      <fdm_port_in>9002</fdm_port_in>
      <fdm_port_out>9003</fdm_port_out>
      <connectionTimeoutMaxCount>5</connectionTimeoutMaxCount>
      <lock_step>1</lock_step>
      <imuName>rover::imu_link::imu_sensor</imuName>
      <modelXYZToAirplaneXForwardZDown degrees='1'>0 0 0 180 0 0</modelXYZToAirplaneXForwardZDown>
      <gazeboXYZToNED degrees='1'>0 0 0 180 0 90</gazeboXYZToNED>
      <control channel='0'>
        <type>VELOCITY</type>
        <jointName>flpb_flw</jointName>
        <multiplier>1</multiplier>
        <offset>0</offset>
        <servo_min>1000</servo_min>
        <servo_max>2000</servo_max>
      </control>
      <control channel='1'>
        <type>VELOCITY</type>
        <jointName>frpb_frw</jointName>
        <multiplier>1</multiplier>
        <offset>0</offset>
        <servo_min>1000</servo_min>
        <servo_max>2000</servo_max>
      </control>
      <control channel='2'>
        <type>VELOCITY</type>
        <jointName>blpb_flw</jointName>
        <multiplier>1</multiplier>
        <offset>0</offset>
        <servo_min>1000</servo_min>
        <servo_max>2000</servo_max>
      </control>
      <control channel='3'>
        <type>VELOCITY</type>
        <jointName>brpb_brw</jointName>
        <multiplier>1</multiplier>
        <offset>0</offset>
        <servo_min>1000</servo_min>
        <servo_max>2000</servo_max>
      </control>
    </plugin>
  </model>
</sdf>

